Workbook
Name GeocodeAddressColumn_IntMainSheet: 'Int Main Sheet'!$F$1

Sheet PHQ Weekly IntOps ATR
L1: Ops ID | M1: Date | N1: Launch Base | O1: Force Strength | P1: Area | Q1: Duration | R1: Achievement | S1: Loss | T1: Remark
L2: 26 | M2: =vlookup(L2,'Operations main Sheet'!A:M,2,0)

Sheet DB-Naxal
A1: Level | B1: Central | C1: Zonal | D1: Sub Zonal | E1: Division | F1: Area Committee | G1: Company | H1: Platoon | I1: Weapon | J1: Electronic Gadget | K1: Status | L1: RPC | M1: Rank
A2: Central | B2: CCM | C2: DKSZC | D2: North Sub Zone | E2: Maad | F2: Kutul | G2: 1 | H2: 16 | I2: LMG | J2: Laptop | K2: Active | L2: Member | M2: CCM
A3: Zonal | B3: PBM | C3: AOBSZC | D3: South Sub Zone | E3: North Bastar | F3: Nelnar | G3: 5 | H3: 17 | I3: AK 47 | J3: Radio | K3: Surrender | L3: Jungle | M3: PB
A4: Sub Zonal | B4: CMC | C4: MMCSZC | D4: West Sub Zone | E4: East Bastar | F4: Indravati | G4: 6 | H4: 1 | I4: SLR | J4: Walky Talky | K4: Dead | L4: Kisan | M4: DVCM
A5: Divisional | B5: CRB | C5: NTSZC | D5: Other | E5: West Bastar | F5: Bayanar | G5: 10 | H5: 2 | I5: INSAS | J5: Smartphone | K5: Encounter | L5: Doctor | M5: CYPC
A6: Area Committee | B6: Other | C6: COBSZC | F6: Amdai | G6: 4 | H6: 32 | I6: 303 Rifle | J6: Scanner | K6: Left | L6: School | M6: ACM
A7: Battalion | C7: SZC | F7: Bodhghat | G7: 7 | I7: 315 Rifle | J7: Tab | K7: Arrest | L7: Education | M7: PPCM
A8: RPC | C8: SMC | F8: Barsur | I8: 12 Bore Gun | J8: Keypad Mobile | L8: Panchayat | M8: RPC
A9: Supply Team | C9: Other | F9: Kiskodo | I9: Carbine | J9: Desktop | L9: Growth | M9: PM
A10: LOS | C10: RKB | F10: Raoghat | I10: 9mm Pistol | J10: Dongal/Jio Fi | L10: Militia Chief | M10: KAMS
F11: Partapur | I11: Single Shot Gun | J11: Icom set | L11: Militia Commander | M11: SMC
F12: Other | I12: Grenade | J12: Laptop,Smartphone | L12: Section Commander | M12: DKCNM
I13: Stungun | L13: Deputy Commander | M13: RCM
I14: SBL | L14: JRD Commander | M14: DKMS
I15: BGL | L15: Incharge | M15: SZCM
I16: Barmer gun | L16: Other | M16: DAKMS
I17: desi ktta | L17: Chife aditor | M17: PPC
I18: INSAS LMG | L18: Plga commander
I19: 51 MOTAR | L19: GRD Member
I20: AK 47 UBGL | L20: CNM
I21: G-3 RIFLE | L21: Commander
I22: Musket Rifle | L22: Supply team
I23: 2 inch Motar | L23: Militia
I24: SLR LMG
I25: 8 AM Rifle

Sheet Naxal Profile
B1: Name | C1: Description | D1: Rank | E1: Level | F1: Central | G1: Zonal | H1: Sub-Zonal | I1: Division | J1: Area Committee | K1: Company | L1: Platoon | M1: RPC | N1: Weapon | O1: Electronic Gadget | P1: Status | Q1: Other Info | R1: Resident | S1: District | T1: Work Area
A2: 1 | B2: नंबाला केशव राव उर्फ बसवराज उर्फ बी.आर. दादा उर्फ गगन्ना उर्फ प्रकाश उर्फ कृष्णा उर्फ विजय उर्फ दारापू नरसिंम्हा रेड्‌डे | C2: पिता स्व. एन वसुुुदेवराव आयु 66/21 पता जियानपेता, कोताम्बली, श्रीकाकुलम, साकिन जियन्नापेटा थाना एवं मंडल कोटाबोमल जिला‐श्रीकाकुलम राज्य‐आंध्र्रप्रदेश | D2: CCM | E2: Central | F2: PBM | N2: AK 47 | P2: Active | Q2: सचिव सीपीआई माओवादी पोलित ब्यूरो
A3: 2 | B3: गणपति उर्फ मुपल्ला लक्ष्मण राव उर्फ जी.एस. उर्फ रमन्ना उर्फ श्रीनिवास उर्फ दयानंद उर्फ चंद्रशेखर उर्फ मलन्ना उर्फ राजन्ना उर्फ बाल रेड्‌डी उर्फ राधा किशन उर्फ जीपी उर्फ शेखर उर्फ सीएस | C3: पिता गोपाल राव उम्र 72/22 वर्ष निवासी बीरपुर जिला‐जगतियाल राज्य‐तेलंगाना | D3: CCM | E3: Central | F3: PBM | P3: Active | Q3: 1. पोलित ब्यूरो सदस्य 2. सेन्ट्रल कमेटी सदस्य
A4: 3 | B4: कत्ताम सुदर्शन उर्फ आनंद उर्फ थेन्टू लक्ष्मीनर सिंम्हा चलम उर्फ टी.एल.एन. चलम उर्फ सुधाकर उर्फ चंटी बालकृष्णा, राम राजू उर्फ आर.आर. उर्फ अरविंद उर्फ सोमन्ना | C4: पिता मल्लेश आयु 64/21 पता ग्राम बेल्लमपल्ली, आदिलाबाद, तेलांगाना निवासी हैदराबाद | D4: CCM | E4: Central | F4: PBM | P4: Dead | Q4: 1. पोलित ब्यूरो सदस्य 2. सेन्ट्रल कमेटी सदस्य 3. सीआरबी सदस्य
A5: 4 | B5: मल्लोजुला वेणुगोपाल राव उर्फ विवेक उर्फ भूपति उर्फ सोनू उर्फ सोनू दादा उर्फ अभय उर्फ राजन उर्फ लच्छन्ना | C5: पिता वेंकटेश उम्र 67 वर्ष निवासी शिवालयम रोड जिला‐पेद्‌दापल्ली राज्य‐तेलंगाना | D5: CCM | E5: Central | F5: PBM | P5: Active | Q5: 1. पोलित ब्यूरो सदस्य 2. सेन्ट्रल कमेटी सदस्य 3. सीआरबी सदस्य
A6: 5 | B6: मिशिर बेसरा उर्फ सुर्निमल | C6: पता किरथान जिला गिरीदीह, झारखंण्ड | D6: CCM | E6: Central | F6: PBM | P6: Dead | Q6: 1. पोलित ब्यूरो सदस्य 2. सेन्ट्रल कमेटी सदस्य 3. ईआरबी सदस्य4. सीएमसी सदस्य 5. इंचार्ज बिहार स्टेट कमेटी
A7: 6 | B7: विवेक चांदरी यादव उर्फ प्रयांग उर्फ विवेक उर्फ करनदा उर्फ लेतरू | C7: साकिन आयु 60/21, पता दल्लुबुधा परासनाथ, थाना तुण्दी, जिला धनबाद, झारखण्ड ा | D7: CCM | E7: Central | F7: CCM | P7: Active | Q7: 1. सेन्ट्रल कमेटी सदस्या 2. ईआरबी सदस्या 3. इंचार्ज झारखंण्ड स्टेट कमेटी
A8: 7 | B8: कादरी नारायण रेड्‌डी उर्फ कोसा उर्फर् गौतम उर्फ साधू उर्फ गोपन्ना उर्फ विनोद उर्फ बूचन्ना | C8: पिता कृष्णा रेड्डी उम्र 66/22 वर्ष निवासी गोपालरावपल्ली सिरिसिल्ला जिला-राजन्ना (करीमनगर) राज्य-तेलंगाना | D8: CCM | E8: Central | F8: CCM | P8: Active | Q8: 1. सेन्ट्रल कमेटी सदस्या2. ईआरबी सदस्या3. इंचार्ज झारखंण्ड स्टेट कमेटी
A9: 8 | B9: थिपिरी तिरूपति उर्फ देवजी उर्फ संजीव उर्फ रमेश उर्फ चेतन उर्फ कुमा उर्फ देवन्ना उर्फ सुदर्शन | D9: CCM | E9: Central | F9: CCM | P9: Active | Q9: 1. सेन्ट्रल कमेटी सदस्य2. सचिव सीएमसी3. सीआरबी सदस्या
A10: 9 | B10: चन्द्रन्ना उर्फ पुलुरी प्रसाद राव उर्फ शंकरन्ना उर्फ शंकर राव उर्फ राम बाबू पिता श्रीनिवास राव | C10: उम्र 65/22 वर्ष निवासी वदकापुर जिला‐पेदापल्ली राज्य‐तेलंगाना | D10: CCM | E10: Central | F10: CCM | P10: Dead | Q10: 1. सेन्ट्रल कमेटी सदस्या2. सीआबी सदस्या3. इंचार्ज तेलांगाना स्टेट कमेटी
A11: 10 | B11: मोदेम बाला कृष्णा उर्फ बालान्ना उर्फ भास्कर उर्फ रामचन्द्र उर्फ राजेन्द्र उर्फ मनोज | C11: पिता वेन्कतियागढ/ वेंकटेश ़आयु 59/22 पता मन्दिकोण्टा एम, धनपुर, जिला वारंगल तेलांगाना | D11: CCM | E11: Central | F11: CCM | P11: Active | Q11: 1. सेन्ट्रल कमेटी सदस्या 2. सीआबी सदस्या 3. इंचार्ज बांसधारा-घुमसार-नागाबली डिवीजन कमेटी 4. उडी़सा स्टेट कमेटी मेम्बर
A12: 11 | B12: कंचन दा उर्फ प्रसाद उर्फ कांचा उर्फ रंजीत बोस उर्फ सुमन | C12: आयु 60/21 पता हावड़ा, दक्षिण बंगाल | D12: CCM | E12: Central | F12: CCM | P12: Dead
A13: 12 | B13: मल्लाराजी रेड्‌डी उर्फ सात्ताना पिता वीरा रेड्‌डी उर्फ संग्राम उर्फ लक्ष्मण उर्फ मुरली पिता वीर रेड्‌डी | C13: पिता वीर रेड्‌डी आयु 71/21 पता सातुलापल्ली वी, मोनथनी एम, जिला करीमनगर पेद्‌दापल्ली तेलांगाना | D13: CCM | E13: Central | F13: CCM | P13: Active
A14: 13 | B14: गणेश उईके उर्फ पक्का हनुमंतु उर्फ राजेश तिवारी उर्फ चमरू दादा उर्फ सोमारू उर्फ मोहन | C14: पिता चन्दरेय उम्र 58/21, पुल्लेमाला, तहसील चंदुर, जिला नालगुण्डा, तेलंगाना | D14: CCM | E14: Central | F14: CCM | P14: Dead
A15: 14 | B15: गजराला रवि उर्फ उदय उर्फ गणेश उर्फ चमरू दादा उर्फ पाका उर्फ हनुमंतुलू | C15: पिता चन्द्रैया, निवासी नालगुण्डा, तेलंगाना | D15: CCM | E15: Central | F15: CMC | P15: Active
A16: 15 | B16: अनाल दा उर्फ तुफान दा उर्फ पतिराम मंजी उर्फ पतिराम मरण्डी | C16: उम्र 56/21 निवास जारावली, थाना दुमरी जिला गिरीडीह झारखण्ड | D16: CCM | E16: Central | F16: CCM | P16: Active
A17: 16 | B17: प्रमोद मिश्रा उर्फ बन बिहारी उर्फ बी.बी. उर्फ नाताजी उर्फ डॉक्टर सर | C17: उम्र 3 जन. 1955 निवास कासमा, थाना औरंगाबाद जिला औरंगाबाद, बिहार | D17: CCM | E17: Central | F17: CCM | P17: Active
A18: 17 | B18: संजय दीपक राव उर्फ विजय | C18: थाने, मुम्बई, महाराष्ट्र | D18: CCM | E18: Central | F18: CCM | P18: Active
A19: 18 | B19: के0 रामचन्द्र रेड्‌डी उर्फ गुडसा उसेण्डी उर्फ विजय उर्फ जुरू उर्फ सुनील उर्फ राजू | C19: उम्र 58/21 निवासी‐ग्राम तिगलागुट्‌टा पल्ली जिला करीमनगर तेलंगाना | D19: CCM | E19: Central | F19: CCM | P19: Dead
A20: 19 | B20: अल्लूरी कृष्णा कुमारी उर्फ जोडे रत्ना बाई उर्फ सरस्वती उर्फ सक्कू बाई | C20: पति मुपल्ला लक्ष्मणराव उर्फ, गणपति 63/22 निवासी - ग्राम बुदरापुपेटा मंडल जिला महबुब नगर तेलंगाना | D20: KAMS | E20: Zonal | G20: DKSZC | H20: North Sub Zone | I20: Maad | N20: AK 47 | P20: Active
A21: 20 | B21: पद्मा उर्फ कल्पना उर्फ सुजातक्का उर्फ मैनीबाई उर्फ मैनक्का पति कोटेश्वर राव उर्फ किशन जी | C21: निवासी - ग्राम पेन्चीकलपेठ जिला महबुब नगर तेलंगाना | D21: DVCM | E21: Zonal | G21: DKSZC | H21: North Sub Zone | I21: Maad | N21: AK 47 | P21: Active
A22: 21 | B22: माडवी हिड़मा उर्फ हिड़मन्ना उर्फ संतोष उम्र 48/2022 | C22: निवासी-ग्राम पुवर्ती थाना जगरगुण्डा जिला सुकमा छ0ग0 | D22: DVCM | E22: Zonal | G22: DKSZC | H22: North Sub Zone | L22: 1 | N22: AK 47 | P22: Active
A23: 22 | B23: अदुमल व्यंकटेस मासा उर्फ सन्तु उम्र 47/21 | C23: निवासी- ग्राम पालोडी थाना किस्टाराम जिला सुकमा छ0ग0 | D23: DVCM | E23: Divisional | G23: DKSZC | H23: North Sub Zone | N23: AK 47 | P23: Active
A24: 23 | B24: अल्लुरी उषा रानी उर्फ नर्मदा पति किरन | C24: निवासी- ग्राम गुदवाड़ा जिला कृष्णा आ0प्र0 | D24: DVCM | E24: Divisional | G24: DKSZC | H24: North Sub Zone | I24: North Bastar | L24: 16 | N24: SLR | P24: Dead
A25: 24 | B25: लोकेती चन्दर उर्फ प्रभाकर उर्फ पादकाल स्वामी उर्फ रवि पिता रामचन्देर उम्र 53/21 | C25: निवासी- ग्राम इसरोजीवाड़ा सदाशिव नगर, मण्डल कामारेड्डी जिला निजामाबाद तेलंगाना | D25: DVCM | E25: Divisional | G25: DKSZC | H25: North Sub Zone | I25: North Bastar | K25: 10 | N25: AK 47 | P25: Active
A26: 25 | B26: तक्कालापल्ली वासुदेव राव उर्फ सतीश उर्फ सुजित उर्फ वासु, | C26: पिता बिखापति राव, उम्र 55/21 निवासी- ग्राम पोलोनी पल्ली लक्ष्मीदेव पेट, व्यंकटपुरम मण्डल जिला वारंगल तेलंगाना | D26: SMC | E26: Zonal | G26: DKSZC | H26: North Sub Zone | K26: 1 | N26: AK 47 | P26: Active | Q26: पूर्व प्रभारी एम.आई पूर्व आर.के.बी. डिवीजन कम्पनी नम्बर 01, 05, 06 का इंचार्ज ईनाम-25 लाख
A27: 26 | B27: रामदेर उर्फ मज्जीदेव उर्फ मजबी, उम्र 52/21 | C27: निवासी- ग्राम मज्जीेमेंडरी (भैरमगढ़) थाना बेदरे जिला बीजापुर छ0ग0 | D27: SMC | E27: Zonal | G27: DKSZC | H27: North Sub Zone | K27: 1 | N27: AK 47 | P27: Active
A28: 27 | B28: लेनगु उर्फ संजीव पिता दनायाह, | C28: उम्र 60/21 निवासी- ग्राम अलवाल जिला रंगारेड्डी तेलंगाना | D28: SZCM | E28: Central | G28: DKSZC | H28: North Sub Zone | N28: AK 47 | P28: Active
A29: 28 | B29: किरन उर्फ किरन दादा | C29: निवासी-विजयवाड़ा सिटी जिला विजयवाड़ा आ0प्र0 | D29: SZCM | E29: Zonal | G29: DKSZC | H29: North Sub Zone | N29: AK 47 | P29: Arrest
A30: 29 | B30: श्याम उर्फ गिरीरेड्डी उर्फ पवनंदा रेड्डी | C30: निवासी- ग्राम पल्लागटा मंडल घनपुर जिला वारंगल तेलंगाना | D30: SZCM | E30: Zonal | G30: DKSZC | H30: North Sub Zone | N30: AK 47 | P30: Active
A31: 30 | B31: कमलेश उर्फ रामकृष्णा उर्फ आर0के0 उर्फ जोरीगेनागाराजू उर्फ विष्णु पिता चित्तैह | C31: जाति अन्य पिछड़ा वर्ग उम्र 01.01.1971 वर्ष निवासी- ग्राम थम्मूला रोड पोरंकी, पेनमल्लुरू मण्डल जिला विजयवाडा | D31: SZCM | E31: Zonal | G31: DKSZC | H31: North Sub Zone | I31: East Bastar | N31: AK 47 | P31: Active
A32: 31 | B32: गिरधर उर्फ नागसु उर्फ मनसु तुमरेटी | C32: निवासी- ग्राम जवेली तहसील एटआपल्ली थाना कसनसूर जिला गढचिरौली | D32: SZCM | E32: Zonal | G32: DKSZC | H32: North Sub Zone | I32: West Bastar | N32: AK 47 | P32: Active
A33: 32 | B33: सुरेन्दर उर्फ सोमा सोढ़ी | C33: निवासी-ग्राम पोलेपट थाना गोलापल्ली जिला सुकमा छ0ग0 | D33: SZCM | E33: Zonal | G33: DKSZC | H33: North Sub Zone | I33: East Bastar | J33: Barsur | N33: AK 47 | P33: Active | Q33: वर्तमान में इसे प्रभारी एसजेडसी सदस्य के पद पर राजनांदगांव बालाघाट डिवीजन में रहना ज्ञात हुआ है।
A34: 33 | B34: चंदू उर्फ चंदर उर्फ ईरा राजू पिता कोमूरैयाह उम्र 36/2016 वर्ष | C34: निवासी- ग्राम टाटिकायला धरमासागर मंडल जिला वारंगल शहर तेलंगाना | D34: DKCNM | E34: Zonal | G34: DKSZC | H34: North Sub Zone | I34: Maad | P34: Active
A35: 34 | B35: रघु उर्फ विकास उर्फ रमेश उर्फ सायलू उर्फ शिवन्ना उर्फ कुवाटी वेंकटेश उर्फ रघु रेड्‌डी उम्र 55/2016 वर्ष | C35: निवासी‐ ग्राम कोटीगल मंडल मन्दुर जिला वारंगल तेलंगाना | D35: DKCNM | E35: Zonal | G35: DKSZC | H35: South Sub Zone | I35: Maad | P35: Dead
A36: 35 | B36: रूसी उर्फ भास्कर उम्र 37/2016 वर्ष | C36: निवासी‐ ग्राम पाटन जवाली कासनसुर महाराष्ट्र | D36: DKCNM | E36: Zonal | G36: DKSZC | H36: North Sub Zone | P36: Dead
A37: 36 | B37: विनय रेड्‌डी उर्फ कुशनाम अशोक रेड्‌डी उर्फ मुरली उर्फ बलदेव पिता सती रेड्‌डी, उम्र 50/2018 | C37: थ्रीमालागिरी, जिला नालगोण्डा, तेलंगाना (वर्ष 2014 में जेल से छुटकर पुन: उसी पद पर कार्य कर रहा है) दिनांक 22.08 | D37: DKCNM | E37: Zonal | G37: DKSZC | H37: North Sub Zone | I37: East Bastar | P37: Arrest
A38: 37 | B38: डोंगा सात्या गंगाधर राव उर्फ वेंगू उर्फ नरसन्ना उम्र 70/22 | C38: साकिन नरेन्द्र पुरम ग्राम पी. गन्नावरम जिला विशाखापट्‌नम आन्ध्रप्रदेश | D38: DKCNM | E38: Zonal | G38: DKSZC | N38: AK 47 | P38: Active
A39: 38 | B39: राजमन उर्फ राजमोहन उर्फ भास्कर उर्फ वेनु उर्फ कंदागटला यादगिरी उर्फ राजमन मण्डावी आरसीएम उम्र 38 वर्ष | C39: निवासी बट्‌टूपाली, हनुमानकोण्डा, मोदीकोंडा, थाना पद्‌मषाली जिला वारंगल, नार्थ तेलंगाना आंध्रपेदश | D39: DKCNM | E39: Divisional | G39: DKSZC | H39: North Sub Zone | I39: Maad | N39: AK 47 | P39: Active
A40: 39 | B40: वेंगू दादा उम्र करीबन 70 वर्ष करीबन | C40: साकिन तेलंगाना | D40: DKCNM | E40: Divisional | G40: DKSZC | H40: North Sub Zone
...

Sheet Int Main Sheet
A1: LT | B1: Int Unique No | C1: Int Content | D1: Name_ | E1: Name | F1: GR | G1: Latitude | H1: Longitude | I1: Strength | J1: Int Confidence | K1: Source | L1: Type | M1: Rank | N1: Area Committee | O1: District | P1: Police Station | R1: Division | S1: Week | T1: Month | U1: Sources Name
A2: 45293 | B2: 1 | D2: dpk | E2: =vlookup(D2,DB!E:F,2,0) -> Deepak Pallo | F2: 19°17'26.999"N 81°5'22.999"E | I2: 18 | K2: CG SIB | L2: Human | M2: =vlookup(D2,DB!E:I,5,0) -> Division | N2: =vlookup(D2,DB!E:G,3,0) -> IndravatiAC | O2: Narayanpur | P2: Orchha | R2: =VLOOKUP(D2,DB!E:H,4,0) -> Maad | S2: =weeknum(A2) -> 1 | T2: =month(A2) -> 1
A3: 45294 | B3: 2 | D3: rnt | E3: =vlookup(D3,DB!E:F,2,0) -> Ranita@Jaymati | F3: 19°34'1.618"N 81°0'1.253"E | I3: 15 | K3: IB | L3: Human | M3: =vlookup(D3,DB!E:I,5,0) -> SubZonal | N3: =vlookup(D3,DB!E:G,3,0) -> KutulAC | O3: Narayanpur | P3: Orchha | R3: =VLOOKUP(D3,DB!E:H,4,0) -> Maad | S3: =weeknum(A3) -> 1 | T3: =month(A3) -> 1
A4: 45295 | B4: 3 | D4: mlj | E4: =vlookup(D4,DB!E:F,2,0) -> Mallojula Venu Gopal@sonu | F4: 19°41'3.091"N 80°40'52.925"E | K4: IB | L4: Human | M4: =vlookup(D4,DB!E:I,5,0) -> Central | N4: =vlookup(D4,DB!E:G,3,0) -> PartapurAC | O4: Narayanpur | P4: Orchha | R4: =VLOOKUP(D4,DB!E:H,4,0) -> NorthBastar | S4: =weeknum(A4) -> 1 | T4: =month(A4) -> 1
A5: 45296 | B5: 4 | D5: cdk | E5: =vlookup(D5,DB!E:F,2,0) -> Chandrakk | I5: 10 | K5: IB | L5: Human | M5: =vlookup(D5,DB!E:I,5,0) | N5: KutulAC | O5: Narayanpur | P5: Orchha | R5: Maad | S5: =weeknum(A5) -> 1 | T5: =month(A5) -> 1
A6: 45297 | B6: 5 | D6: bdr | E6: =vlookup(D6,DB!E:F,2,0) -> Badru | F6: 19°40'42.323"N 81°2'33.760"E | K6: CG SIB | L6: Human | M6: =vlookup(D6,DB!E:I,5,0) -> AreaCommittee | N6: =vlookup(D6,DB!E:G,3,0) -> KutulAC | O6: Narayanpur | P6: Orchha | R6: =VLOOKUP(D6,DB!E:H,4,0) -> Maad | S6: =weeknum(A6) -> 1 | T6: =month(A6) -> 1
A7: 45298 | B7: 6 | D7: mur | E7: =vlookup(D7,DB!E:F,2,0) -> Murli Salam | I7: 25 | K7: CG SIB | L7: Human | M7: =vlookup(D7,DB!E:I,5,0) -> Division | N7: =vlookup(D7,DB!E:G,3,0) -> AmdaiAC | O7: Narayanpur | P7: Chhotedongar | R7: =VLOOKUP(D7,DB!E:H,4,0) -> EastBastar | S7: =weeknum(A7) -> 2 | T7: =month(A7) -> 1
A8: 45299 | B8: 7 | D8: rmd | E8: =vlookup(D8,DB!E:F,2,0) -> Ramdas | F8: 19°17'19.000"N 81°10'10.999"E | K8: CG SIB | L8: Human | M8: =vlookup(D8,DB!E:I,5,0) -> AreaCommittee | N8: =vlookup(D8,DB!E:G,3,0) -> IndravatiAC | O8: Narayanpur | P8: Orchha | R8: =VLOOKUP(D8,DB!E:H,4,0) -> Maad | S8: =weeknum(A8) -> 2 | T8: =month(A8) -> 1
A9: 45300 | B9: 8 | D9: vsu | E9: =vlookup(D9,DB!E:F,2,0) -> Veshu | F9: 19°32'46.842"N 81°2'57.584"E | I9: 17 | K9: CG SIB | L9: Human | M9: =vlookup(D9,DB!E:I,5,0) -> AreaCommittee | N9: =vlookup(D9,DB!E:G,3,0) -> KutulAC | O9: Narayanpur | P9: Kohkameta | R9: =VLOOKUP(D9,DB!E:H,4,0) -> Maad | S9: =weeknum(A9) -> 2 | T9: =month(A9) -> 1
A10: 45301 | B10: 9 | D10: bdr | E10: =vlookup(D10,DB!E:F,2,0) -> Badru | F10: 19°40'42.323"N 81°2'33.760"E | I10: 4 | K10: CG SIB | L10: Human | M10: =vlookup(D10,DB!E:I,5,0) -> AreaCommittee | N10: =vlookup(D10,DB!E:G,3,0) -> KutulAC | O10: Narayanpur | P10: Orchha | R10: =VLOOKUP(D10,DB!E:H,4,0) -> Maad | S10: =weeknum(A10) -> 2 | T10: =month(A10) -> 1
A11: 45302 | B11: 10 | D11: bdu | E11: =vlookup(D11,DB!E:F,2,0) -> Budru@Badru | F11: 19°25'20.323"N 81°10'14.678"E | I11: 10 | K11: CG SIB | L11: Human | M11: =vlookup(D11,DB!E:I,5,0) -> AreaCommittee | N11: =vlookup(D11,DB!E:G,3,0) -> NelnarAC | O11: Narayanpur | P11: Kohkameta | R11: =VLOOKUP(D11,DB!E:H,4,0) -> Maad | S11: =weeknum(A11) -> 2 | T11: =month(A11) -> 1
A12: 45303 | B12: 11 | D12: rjta | E12: =vlookup(D12,DB!E:F,2,0) -> Ranjeeta Mandavi | F12: 19.734486° 80.932348° | I12: 6 | K12: CG SIB | L12: Human | M12: =vlookup(D12,DB!E:I,5,0) -> LOS | N12: =vlookup(D12,DB!E:G,3,0) -> KutulAC | O12: Narayanpur | P12: Sonpur | R12: =VLOOKUP(D12,DB!E:H,4,0) -> Maad | S12: =weeknum(A12) -> 2 | T12: =month(A12) -> 1
A13: 45304 | B13: 12 | D13: rju | E13: =vlookup(D13,DB!E:F,2,0) -> Raju | F13: 19°54'31.849"N 80°55'25.097"E | I13: 22 | K13: CG SIB | L13: Human | M13: =vlookup(D13,DB!E:I,5,0) -> Division | N13: =vlookup(D13,DB!E:G,3,0) -> PartapurAC | O13: Narayanpur | P13: Sonpur | R13: =VLOOKUP(D13,DB!E:H,4,0) -> NorthBastar | S13: =weeknum(A13) -> 2 | T13: =month(A13) -> 1
A14: 45305 | B14: 13 | D14: rcd | E14: =vlookup(D14,DB!E:F,2,0) -> Ramchandra | F14: 19°41'26.848"N 80°48'54.706"E | I14: 30 | K14: CG SIB | L14: Human | M14: =vlookup(D14,DB!E:I,5,0) -> Division | N14: KutulAC | O14: Narayanpur | P14: Orchha | R14: Maad | S14: =weeknum(A14) -> 3 | T14: =month(A14) -> 1
A15: 45306 | B15: 14 | D15: rna | E15: =vlookup(D15,DB!E:F,2,0) -> Reena | F15: 19°34'30.637"N 80°58'6.679"E | I15: 10 | K15: CG SIB | L15: Human | M15: =vlookup(D15,DB!E:I,5,0) -> Division | N15: =vlookup(D15,DB!E:G,3,0) -> KutulAC | O15: Narayanpur | P15: Kohkameta | R15: =VLOOKUP(D15,DB!E:H,4,0) -> Maad | S15: =weeknum(A15) -> 3 | T15: =month(A15) -> 1
A16: 45307 | B16: 15 | D16: smd | E16: =vlookup(D16,DB!E:F,2,0) -> Somdu Madkam | F16: 19°29'17.545"N 81°16'3.857"E | I16: 8 | K16: CG SIB | L16: Human | M16: =vlookup(D16,DB!E:I,5,0) -> AreaCommittee | N16: =vlookup(D16,DB!E:G,3,0) -> NelnarAC | O16: Narayanpur | P16: Kohkameta | R16: =VLOOKUP(D16,DB!E:H,4,0) -> Maad | S16: =weeknum(A16) -> 3 | T16: =month(A16) -> 1
A17: 45308 | B17: 16 | D17: snu | E17: =vlookup(D17,DB!E:F,2,0) -> Sannu | F17: 19.325480° 81.081788° | I17: 12 | K17: CG SIB | L17: Human | M17: =vlookup(D17,DB!E:I,5,0) -> AreaCommittee | N17: =vlookup(D17,DB!E:G,3,0) -> IndravatiAC | O17: Narayanpur | P17: Orchha | R17: =VLOOKUP(D17,DB!E:H,4,0) -> Maad | S17: =weeknum(A17) -> 3 | T17: =month(A17) -> 1
A18: 45309 | B18: 17 | D18: ukn | E18: =vlookup(D18,DB!E:F,2,0) -> Unknown | F18: 19°29'3.415"N 81°11'59.762"E | I18: 8 | K18: CG SIB | L18: Human | M18: =vlookup(D18,DB!E:I,5,0) | N18: NelnarAC | O18: Narayanpur | P18: Kohkameta | R18: Maad | S18: =weeknum(A18) -> 3 | T18: =month(A18) -> 1
A19: 45310 | B19: 18 | D19: skr | E19: =vlookup(D19,DB!E:F,2,0) -> Sankar | F19: 19.412372° 81.453192° | I19: 8 | K19: CG SIB | L19: Human | M19: =vlookup(D19,DB!E:I,5,0) -> AreaCommittee | N19: =vlookup(D19,DB!E:G,3,0) -> BarsurAC | O19: Narayanpur | P19: Chhotedongar | R19: =VLOOKUP(D19,DB!E:H,4,0) -> EastBastar | S19: =weeknum(A19) -> 3 | T19: =month(A19) -> 1
A20: 45311 | B20: 19 | D20: skl | E20: =vlookup(D20,DB!E:F,2,0) -> Sukhlal Kunjam | F20: 19°31'5.059"N 81°0'24.559"E | I20: 8 | K20: CG SIB | L20: Human | M20: =vlookup(D20,DB!E:I,5,0) -> Division | N20: =vlookup(D20,DB!E:G,3,0) -> KutulAC | O20: Narayanpur | P20: Orchha | R20: =VLOOKUP(D20,DB!E:H,4,0) -> Maad | S20: =weeknum(A20) -> 3 | T20: =month(A20) -> 1
A21: 45312 | B21: 20 | D21: lkmu | E21: =vlookup(D21,DB!E:F,2,0) -> Lakhmu Kawachi | F21: 19.960931° 81.286923° | I21: 6 | K21: CG SIB | L21: Human | M21: =vlookup(D21,DB!E:I,5,0) -> AreaCommittee | N21: =vlookup(D21,DB!E:G,3,0) -> KiskodoAC | O21: Narayanpur | P21: Erka | R21: =VLOOKUP(D21,DB!E:H,4,0) -> NorthBastar | S21: =weeknum(A21) -> 4 | T21: =month(A21) -> 1
A22: 45313 | B22: 21 | D22: rjm | E22: =vlookup(D22,DB!E:F,2,0) -> Rajman | F22: 19°22'48.486"N 81°2'53.902"E | K22: CG SIB | L22: Human | M22: =vlookup(D22,DB!E:I,5,0) -> AreaCommittee | N22: KutulAC | O22: Narayanpur | P22: Kohkameta | R22: Maad | S22: =weeknum(A22) -> 4 | T22: =month(A22) -> 1
A23: 45314 | B23: 22 | D23: pml | E23: =vlookup(D23,DB!E:F,2,0) -> Pramila | F23: 19°27'19.300"N 81°7'54.048"E | I23: 8 | K23: CG SIB | L23: Human | M23: =vlookup(D23,DB!E:I,5,0) -> AreaCommittee | N23: =vlookup(D23,DB!E:G,3,0) -> NelnarAC | O23: Narayanpur | P23: Kohkameta | R23: =VLOOKUP(D23,DB!E:H,4,0) -> Maad | S23: =weeknum(A23) -> 4 | T23: =month(A23) -> 1
A24: 45315 | B24: 23 | D24: srs | E24: =vlookup(D24,DB!E:F,2,0) -> Suresh Salam | F24: 19°19'27.365"N 81°20'42.353"E | I24: 15 | K24: CG SIB | L24: Human | M24: =vlookup(D24,DB!E:I,5,0) -> AreaCommittee | N24: =vlookup(D24,DB!E:G,3,0) -> AmdaiAC | O24: Narayanpur | P24: Chhotedongar | R24: =VLOOKUP(D24,DB!E:H,4,0) -> EastBastar | S24: =weeknum(A24) -> 4 | T24: =month(A24) -> 1
A25: 45323 | B25: 24 | C25: Orchha Thana se lgbhag 14 km. pashchim disha gram ader me dinak 1.2.2024 ke pratha 06 baje se orchha LGS kamandar ramdash, sukhlal sahit 14-15 mawadiyoo ka upashthithi ki suchna hai | D25: rmd | E25: =vlookup(D25,DB!E:F,2,0) -> Ramdas | F25: 19°17'26.999"N 81°5'22.999"E | I25: 14 | K25: CG SIB | L25: Human | M25: =vlookup(D25,DB!E:I,5,0) -> AreaCommittee | N25: =vlookup(D25,DB!E:G,3,0) -> IndravatiAC | O25: Narayanpur | P25: Orchha | R25: =VLOOKUP(D25,DB!E:H,4,0) -> Maad | S25: =weeknum(A25) -> 5 | T25: =month(A25) -> 2
A26: 45326 | B26: 25 | C26: Than sonpur se lgbhag 18 km. dkchid disha gram kangoli me dinakh 04.02.2024 ko paralkot LOS kamandar mase ke sath 09-10 sashastra mavowadiyo ke upasthithi ki suchna hai | D26: mse | E26: =vlookup(D26,DB!E:F,2,0) -> Mase | F26: 19.638311° 80.905661° | I26: 9 | K26: IB | L26: Human | M26: =vlookup(D26,DB!E:I,5,0) -> AreaCommittee | N26: =vlookup(D26,DB!E:G,3,0) -> KutulAC | O26: Narayanpur | P26: Sonpur | R26: =VLOOKUP(D26,DB!E:H,4,0) -> Maad | S26: =weeknum(A26) -> 6 | T26: =month(A26) -> 2
A27: 45327 | B27: 26 | D27: dpk | E27: =vlookup(D27,DB!E:F,2,0) -> Deepak Pallo | F27: C | I27: 15 | K27: CG SIB | L27: Human | M27: =vlookup(D27,DB!E:I,5,0) -> Division | N27: =vlookup(D27,DB!E:G,3,0) -> IndravatiAC | O27: Narayanpur | P27: Orchha | R27: =VLOOKUP(D27,DB!E:H,4,0) -> Maad | S27: =weeknum(A27) -> 6 | T27: =month(A27) -> 2
A28: 45328 | B28: 27 | C28: Thana Orchha se kariban 12 km. purv disha gram bhatbeda me dinakh 06.2.2024 ke pratha se indrawati eriya kameti sachiv deepak ke sath 10-12 maavowadiyo ke upashthithi rhkar gram bhatbeda jabgunda rothad eriya me lgathar braman karne ki suchna hai | D28: dpk | E28: =vlookup(D28,DB!E:F,2,0) -> Deepak Pallo | F28: 19°17'6.720"N 81°8'17.027"E | I28: 10 | K28: CG SIB | L28: Human | M28: =vlookup(D28,DB!E:I,5,0) -> Division | N28: =vlookup(D28,DB!E:G,3,0) -> IndravatiAC | O28: Narayanpur | P28: Orchha | R28: =VLOOKUP(D28,DB!E:H,4,0) -> Maad | S28: =weeknum(A28) -> 6 | T28: =month(A28) -> 2
A29: 45329 | B29: 28 | D29: arb | E29: =vlookup(D29,DB!E:F,2,0) -> Arab@Kamlesh | F29: 19°25'20.323"N 81°10'14.678"E | I29: 13 | K29: CG SIB | L29: Human | M29: =vlookup(D29,DB!E:I,5,0) -> Division | N29: =vlookup(D29,DB!E:G,3,0) -> NelnarAC | O29: Narayanpur | P29: Orchha | R29: =VLOOKUP(D29,DB!E:H,4,0) -> Maad | S29: =weeknum(A29) -> 6 | T29: =month(A29) -> 2
A30: 45330 | B30: 29 | D30: rna | E30: =vlookup(D30,DB!E:F,2,0) -> Reena | F30: 19.568592° 80.966547° | I30: 12 | K30: Local Human | L30: Human | M30: =vlookup(D30,DB!E:I,5,0) -> Division | N30: =vlookup(D30,DB!E:G,3,0) -> KutulAC | O30: Narayanpur | P30: Kohkameta | R30: =VLOOKUP(D30,DB!E:H,4,0) -> Maad | S30: =weeknum(A30) -> 6 | T30: =month(A30) -> 2
A31: 45331 | B31: 30 | C31: Orcha se lgbhag 15 km. purva disha garam kakavadaa me dinakh 09.02.2024 ke pratha se indrawati eriya kameti sachiv DVCM deepak sahit lgbhag 18-20 sashatra maovadiyo ke upsthithi ki suchna hai | D31: dpk | E31: =vlookup(D31,DB!E:F,2,0) -> Deepak Pallo | I31: 18 | K31: CG SIB | L31: Human | M31: =vlookup(D31,DB!E:I,5,0) -> Division | N31: =vlookup(D31,DB!E:G,3,0) -> IndravatiAC | O31: Narayanpur | P31: Orchha | R31: =VLOOKUP(D31,DB!E:H,4,0) -> Maad | S31: =weeknum(A31) -> 6 | T31: =month(A31) -> 2
A32: 45331 | B32: 31 | D32: pdi | E32: =vlookup(D32,DB!E:F,2,0) -> Pandi@Dinesh | I32: 7 | K32: CG SIB | L32: Human | M32: =vlookup(D32,DB!E:I,5,0) -> AreaCommittee | N32: =vlookup(D32,DB!E:G,3,0) -> KutulAC | O32: Narayanpur | P32: Orchha | R32: =VLOOKUP(D32,DB!E:H,4,0) -> Maad | S32: =weeknum(A32) -> 6 | T32: =month(A32) -> 2
A33: 45331 | B33: 32 | D33: smd | E33: =vlookup(D33,DB!E:F,2,0) -> Somdu Madkam | F33: 19°29'10.590"N 81°9'26.179"E | I33: 10 | K33: IB | L33: Human | M33: =vlookup(D33,DB!E:I,5,0) -> AreaCommittee | N33: =vlookup(D33,DB!E:G,3,0) -> NelnarAC | O33: Narayanpur | P33: Kohkameta | R33: =VLOOKUP(D33,DB!E:H,4,0) -> Maad | S33: =weeknum(A33) -> 6 | T33: =month(A33) -> 2
A34: 45332 | B34: 33 | C34: Thana koylibeda se 20 km. dhkchid gram gome ke ashram para se 02 km paschim disha pahadi ke pass jungle ea dinakha 10.2.2024 ke pratha se kampany number 5 ke kamandar DVCM Raju Salam sahit 25-26 sashatra maovadiyo ki upsthithi ki suchna hai | D34: rju | E34: =vlookup(D34,DB!E:F,2,0) -> Raju | F34: 19°54'31.849"N 80°55'25.097"E | I34: 25 | K34: Local Human | L34: Human | M34: =vlookup(D34,DB!E:I,5,0) -> Division | N34: PartapurAC | O34: Narayanpur | P34: Sonpur | R34: =VLOOKUP(D34,DB!E:H,4,0) -> NorthBastar | S34: =weeknum(A34) -> 6 | T34: =month(A34) -> 2
A35: 45333 | B35: 34 | D35: kml | E35: =vlookup(D35,DB!E:F,2,0) -> Kamlesh | I35: 8 | K35: IB | L35: Human | M35: =vlookup(D35,DB!E:I,5,0) -> Division | N35: NelnarAC | O35: Narayanpur | P35: Orchha | R35: =VLOOKUP(D35,DB!E:H,4,0) -> Maad | S35: =weeknum(A35) -> 7 | T35: =month(A35) -> 2
A36: 45333 | B36: 35 | D36: dpk | E36: =vlookup(D36,DB!E:F,2,0) -> Deepak Pallo | I36: 18 | K36: IB | L36: Human | M36: =vlookup(D36,DB!E:I,5,0) -> Division | N36: =vlookup(D36,DB!E:G,3,0) -> IndravatiAC | O36: Narayanpur | P36: Orchha | R36: =VLOOKUP(D36,DB!E:H,4,0) -> Maad | S36: =weeknum(A36) -> 7 | T36: =month(A36) -> 2
A37: 45335 | B37: 36 | C37: Orcha se lgbhag 18 km paschim disha gram gomagal me dinakh 13.02.2024 ke maad divition sachiv ranita urf jaimati ke sath lgbhag 15-20 sashatr maovadiyo ke upshthithi ki suchna hai | D37: rnt | E37: =vlookup(D37,DB!E:F,2,0) -> Ranita@Jaymati | F37: 19°25'34.086"N 81°4'17.418"E | I37: 15 | K37: CG SIB | L37: Human | M37: =vlookup(D37,DB!E:I,5,0) -> SubZonal | N37: =vlookup(D37,DB!E:G,3,0) -> KutulAC | O37: Narayanpur | P37: Orchha | R37: =VLOOKUP(D37,DB!E:H,4,0) -> Maad | S37: =weeknum(A37) -> 7 | T37: =month(A37) -> 2
A38: 45335 | B38: 37 | D38: mse | E38: =vlookup(D38,DB!E:F,2,0) -> Mase | F38: 19.691036° 80.844588° | I38: 5 | K38: IB | L38: Human | M38: =vlookup(D38,DB!E:I,5,0) -> AreaCommittee | N38: =vlookup(D38,DB!E:G,3,0) -> KutulAC | O38: Narayanpur | P38: Orchha | R38: =VLOOKUP(D38,DB!E:H,4,0) -> Maad | S38: =weeknum(A38) -> 7 | T38: =month(A38) -> 2
A39: 45335 | B39: 38 | D39: rnt | E39: =vlookup(D39,DB!E:F,2,0) -> Ranita@Jaymati | F39: 19°25'34.086"N 81°4'17.418"E | I39: 15 | K39: CG SIB | L39: Human | M39: =vlookup(D39,DB!E:I,5,0) -> SubZonal | N39: =vlookup(D39,DB!E:G,3,0) -> KutulAC | O39: Narayanpur | P39: Orchha | R39: =VLOOKUP(D39,DB!E:H,4,0) -> Maad | S39: =weeknum(A39) -> 7 | T39: =month(A39) -> 2
A40: 45335 | B40: 39 | C40: Kohkameta se 10 km paschim disha and thana sonpur se 08 km. disha gram hikmeta me dinakh 13.02.2024 ke pratha se kutul eriya kameti ranjeet ke sath 07-08 sashatr maovadiyo ke upsthithi ki suchna hai | D40: rjt | E40: =vlookup(D40,DB!E:F,2,0) -> Ranjit | F40: 19°38'47.753"N 81°0'48.949"E | I40: 7 | K40: CG SIB | L40: Human | M40: =vlookup(D40,DB!E:I,5,0) -> AreaCommittee | N40: =vlookup(D40,DB!E:G,3,0) -> KutulAC | O40: Narayanpur | P40: Kohkameta | R40: =VLOOKUP(D40,DB!E:H,4,0) -> Maad | S40: =weeknum(A40) -> 7 | T40: =month(A40) -> 2
...

Sheet Profile
A1: Id | B1: Name | C1: Rank | D1: Reward | E1: Weapon | F1: Divison | G1: Area Commitee | H1: Company | I1: Platoon | J1: Work Area | K1: LOS | L1: LGS | M1: Jury | N1: Description
A2: 1 | B2: uackyk ds'ko jko mQZ clojkt mQZ ch”vkj” nknk mQZ xxUuk mQZ izdk'k mQZ d`"-kk mQZ fot( mQZ nkjkiw ujflaEgk jsM~Ms firk Lo” ]u olqqqnsojko vk(q 66@21 irk ft(kuisrk] dksRkkEcyh] Jhdkdqye] lkfdu ft(UukisVuackyk ds'ko jko mQZ clojkt mQZ ch”vkj” nknk mQZ xxUuk mQZ izdk'k mQZ d`"-kk mQZ fot( mQZ nkjkiw ujflaEgk jsM~Ms firk Lo” ]u olqqqnsojko vk(q 66@21 irk ft(kuisrk] dksRkkEcyh] Jhdkdqye] lkfdu ft(UukisV | C2: lfpo lhihvkbZ ekvksoknh iksfyr C;wjks | D2: 1 djksM+ | E2: ,ds&47
A3: 2 | B3: x.kifr mQZ eqiYyk y{e.k jko mQZ th-,l- mQZ jeUuk mQZ Jhfuokl mQZ n;kuan mQZ panz'ks[kj mQZ eyUuk mQZ jktUuk mQZ cky jsM~Mh mQZ jk/kk fd'ku mQZ thih mQZ 'ks[kj mQZ lh,l firk xksiky jko mez 72@22 o"kZ fuoklh chjiqj ftyk&txfr;ky jkT;&rsyaxkuk | C3: iksfyr C;wjks lnL;]lsUVªy desVh lnL; | D3: 1 djksM+ | E3: ,ds&47
A4: 3 | B4: dRrke lqn'kZu mQZ vkuan mQZ FksUVw y{ehuj flaEgk pye mQZ Vh-,y-,u- pye mQZ lq/kkdj mQZ paVh ckyd`".kk] jke jktw mQZ vkj-vkj- mQZ vjfoan mQZ lkseUuk firk eYys'k vk;q 64@21 irk xzke csYyeiYyh] vkfnykckn] rsykaxkuk fuoklh gSnjkckn | C4: iksfyr C;wjks lnL;]lsUVªy desVh lnL;]lhvkjch lnL; | D4: 1 djksM+ | E4: ,ds&47
A5: 4 | B5: eykstqYyk osuqxksiky mQZ Hkwifr mQZ lksuw mQZ vHk; firk osudfr;k] vk;q 59@21] irk xzke isn~nkiYyh] djheuxj ftyk rsykaxkuk eYykstqyk os.kqxksiky jko mQZ foosd mQZ Hkwifr mQZ lksuw mQZ lksuw nknk mQZ vHk; mQZ jktu mQZ yPNUuk firk osadVs'k mez 67 o"kZ fuoklh f'koky;e jksM ftyk&isn~nkiYyh jkT;&rsyaxkuk | C5: iksfyr C;wjks lnL;]lsUVªy desVh lnL;]lhvkjch lnL; | D5: 1 djksM+ | E5: ,ds&47
A6: 5 | B6: fef'kj csljk mQZ lqfuZey firk niZu csljk vk;q 62@21 irk lUrky] enqUnh] irk fdjFkku ftyk fxjhnhg] >kj[ka.M | C6: iksfyr C;wjks lnL;] lsUVªy desVh lnL;]bZvkjch lnL;] lh,elh lnL;]bapktZ fcgkj LVsV desVh | D6: 1 djksM | E6: ,ds&47
A7: 6 | B7: foosd pkanjh ;kno mQZ iz;kax mQZ foosd mQZ djunk mQZ ysr: firk Lo- pd: eqjew] lkfdu vk;q 60@21] irk nYyqcq/kk ijklukFk] Fkkuk rq.nh] ftyk /kuckn] >kj[k.M | C7: lsUVªy desVh lnL;k] bZvkjch lnL;k] bapktZ >kj[ka.M LVsV desVh | D7: 40 yk[k | E7: ,ds&47
A8: 7 | B8: dknjh ukjk;.k jsM~Mh mQZ dkslk mQZZ xkSre mQZ lk/kw mQZ xksiUuk mQZ fouksn mQZ cwpUuk firk d`".kk jsM~Mh mez 66@22 o"kZ fuoklh xksikyjkoiYyh flfjflYyk ftyk&jktUuk ¼djheuxj½ jkT;&rsyaxkuk | C8: lsUVªy desVh lnL;]lhvkjch lnL;]bapktZ vkjihlh bu Mhds | D8: 40 yk[k | E8: ,ds&47
A9: 8 | B9: fFkfijh fr:ifr mQZ nsoth mQZ latho mQZ jes'k mQZ psru mQZ dqek mQZ nsoUuk mQZ lqn'kZu mez 62@22 o"kZ firk osadVkujlS;k o"kZ fuoklh H.N. 5-2-358 vacsMdj uxj dks:ryk ftyk&txfr;ky jkT;&rsyaxkuk | C9: lsUVªy desVh lnL;]lfpo lh,elh]lhvkjch lnL;k | D9: 40 yk[k | E9: ,ds&47
A10: 9 | B10: pUnzUuk mQZ iqYkqjh izlkn jko mQZ 'kadjUuk mQZ 'kadj jko mQZ jke ckcw firk Jhfuokl jko mez 65@22 o"kZ fuoklh ondkiqj ftyk&isnkiYyh jkT;&rsyaxkuk | C10: lsUVªy desVh lnL;k]lhvkch lnL;k]bapktZ rsykaxkuk LVsV desVh | D10: 40 yk[k | E10: ,ds&47
A11: 10 | B11: eksnse ckyk d`".kk mQZ ckykUuk mQZ HkkLdj mQZ jkepUnz mQZ jktsUnz mQZ eukst firk osUdfr;kx<@ osadVs'k +vk;q 59@22 irk efUndks.Vk ,e] /kuiqj] ftyk okjaxy rsykaxkuk | C11: lsUVªy]desVh]lnL;k]lhvkch]lnL;k]bapktZ]ckal/kkjk&?kqelkj&ukxkcyh]fMohtu desVh]mMh+lk LVsV desVh esEcj | D11: 40 yk[k | E11: ,ds&47
A12: 11 | B12: dapu nk mQZ izlkn mQZ dkapk mQZ jathr cksl mQZ lqeu vk;q 60@21 irk gkoM+k] nf{k.k caxky | C12: lsUVªy desVh lnL;k]bZvkjch lnL;k]bapktZ nf{k.k caxky LVsV desVh | D12: 40 yk[k | E12: ,ds&47
A13: 12 | B13: eYykjkth jsM~Mh mQZ lkRrkuk firk ohjk jsM~Mh mQZ laxzke mQZ y{e.k mQZ eqjyh firk ohj jsM~Mh vk;q 71@21 irk lkrqykiYyh oh] eksuFkuh ,e] ftyk djheuxj isn~nkiYyh rsykaxkuk | C13: lsUVªy desVh lnL;k]bapktZ vksfMlk LVsV desVh]lhvkjch lnL;k | D13: 40 yk[k | E13: ,ds&47
... A37: 36 | B37: fou; jsM~Mh mQZ dq'kuke v'kksd jsM~Mh mQZ eqjyh mQZ cynso firk lrh jsM~Mh] mez 50@2018 Fkzhekykfxjh] ftyk ukyxks.Mk] rsyaxkuk ¼o"kZ 2014 esa tsy ls NqVdj iqu% mlh in ij dk;Z dj jgk gS½] fnukad 22-08-23 dks tcyiqj ¼e/;izns'k½ ,Vh,l ds }kjk fxj¶rkj fd;k x;k gSA | C37: iwoZ esa &lfpo bZLV cLrj fMohtu] vkj-ds-ch- fMohtu bapktZ] Mh-ds-,l-tsM-lh lnL; | D37: bZuke& 25 yk[k | E37: ,ds&47
A38: 37 | B38: Mksaxk lkR;k xaxk/kj jko mQZ osaxw mQZ ujlUuk mez 70@22] lkfdu ujsUnz iqje xzke ih- xUukoje ftyk fo’kk[kkiV~ue vkU/kzizns’k | C38: Mh-ds-,l-tsM-lh] LVsV feysVªh deh'ku lnL; | E38: ,ds&47
A39: 38 | B39: jkteu mQZ jkteksgu mQZ HkkLdj mQZ osuq mQZ dankxVyk ;knfxjh mQZ jkteu e.Mkoh vkjlh,e mez 38 o"kZ] fuoklh cV~Vwikyh] guqekudks.Mk] eksnhdksaMk] Fkkuk in~e"kkyh ftyk okjaxy] ukFkZ rsyaxkuk vka/kzisn’k | C39: Mh-ds-,l-tsM-lh lnL;] bapktZ mRrj cLrj fMohtu] csjk if=dk dk phQ ,fMVj] | D39: bZuke&25 yk[k | E39: ,ds&47
A40: 39 | B40: osaxw nknk mez djhcu 70 o"kZ djhcu lkfdu rsyaxkuk | C40: Mh-ds-,l-tsM-lh lnL;] Mh-ds- Vh-Mh- izHkkjh | E40: ,ds&47
A41: 40 | B41: :ih mQZ t;k ifr lrh’k mQZ dksik mQZ NRrhl djhcu mez 52 o"kZ fuoklh egcwc uxj vkU/kzizns’k] gqfy;k & dn 5-7 QhV djhcu] jax xksjh] 'kjhj& [kMk cnu]] psgjk yEck] dkys yEcs cky j[krh gS] vka[kks esa p’ek yxkrh gS] fgUnh] gYch] xks.Mh] ejkBh] rsyxw Hkk"kk cksyrh gSA | C41: ,l-tsM-lh-,e--] Mh0ds0 tksu ch-lh-Vh-,l- bapktZ] ¼csfld dE;wfuLV Vªsfuax Ldqy½ | E41: ,ds&47 okdhVkdh lV
A42: 41 | B42: foosd mQZ fcjlk mez 50 o"kZ djhcu lkfdu rsyaxkuk | C42: Mh-ds-,l-tsM-lh lnL;] osaxw dk Mh-ds- Vh-Mh- lgk;d | E42: ,ds&47
A43: 42 | B43: ikik jko lkfdu vkU/kzizns'k | C43: Mh-ds-,l-tsM-lh lnL;] if'pe cLrj fMohtu izHkkjh] feM+axqj if=dk dk phQ ,fMVj | E43: ,ds&47
A44: 43 | B44: fodkl lkfdu rsyaxkuk | C44: Mh-ds-,l-tsM-lh lnL;] nf{k.k cLrj fMohtu izHkkjh | E44: ,ds&47
A45: 44 | B45: izHkkdj lkfdu vkU/kzizns'k | C45: Mh-ds-,l-tsM-lh lnL;] if'pe cLrj C;wjks bapktZ | E45: ,ds&47
A46: 45 | B46: jru mQZ fnus'k mQZ iqlq mQZ m/keflag fuoklh x<fpjkSyh | C46: mRrj C;wjks lIykbZ Vhe bapktZ ¼vkj-lh-,e-½ | E46: ,ds&47
A47: 46 | B47: ds0 jkepUnz jsM~Mh mQZ xqMlk mls.Mh mQZ fot; mQZ tq: mQZ lquhy mQZ jktw mez 58@21 fuoklh&xzke frxykxqV~Vk iYyh ftyk djheuxj rsyaxkuk | C47: lh-lh-,e-] bapktZ mRrj jhtuy C;wjks] bapktZ@ ¼Mhds,ltsMlh½] ,l-,e-lh-] iwoZ esa Mh-ds-,l-tsM-lh lnL;@izHkkjh iwohZ cLrj fMohtu | D47: 25 yk[k
A48: 47 | B48: jkensj mQZ eTthnso mQZ etch] mez 52@21 fuoklh& xzke eTthsesaMjh ¼HkSjex<+½ Fkkuk csnjs ftyk chtkiqj N0x0 | C48: Mh-ds-,l-tsM-lh lnL;, lfpo ,l-,e-lh-, bZuke&25 yk[k | D48: 25 yk[k
A49: 48 | B49: rDdkykiYyh oklqnso jko mQZ lrh'k mQZ lqftr mQZ oklq] firk fc[kkifr jko] mez 55@21 fuoklh& xzke iksyksuh iYyh y{ehnso isV] O;adViqje e.My ftyk okjaxy rsyaxkuk | C49: Mh-ds-,l-tsM-lh lnL;, iwoZ izHkkjh ,e-vkbZ] iwoZ vkj-ds-ch- fMohtu dEiuh uEcj 01] 05] 06 dk bapktZ | D49: 25 yk[k
A50: 49 | B50: vnqey O;adVsl eklk mQZ lUrq mez 47@21] fuoklh& xzke ikyksMh Fkkuk fdLVkjke ftyk lqdek N0x0 | C50: Mh-ds-,l-tsM-lh lnL;] ,l-,l-lh- lnL;] bZuke&25 yk[k | D50: 25 yk[k | E50: ,ds&47
A51: 50 | B51: ekMoh fgM+ek mQZ fgM+eUuk mQZ larks"k mez 48@2022] fuoklh&xzke iqorhZ Fkkuk txjxq.Mk ftyk lqdek N0x0 | C51: Mh-ds-,l-tsM-lh lnL;@dek.Mj] ih,yth, cVk0 ua0&01 | D51: 25 yk[k | E51: ,ds&47
A52: 51 | B52: Mksaxk lkR;k xaxk/kj jko mQZ osaxw mQZ ujlUuk mez 70@22] lkfdu ujsUnz iqje xzke ih- xUukoje ftyk fo’kk[kkiV~ue vkU/kzizns’k | C52: Mh-ds-,l-tsM-lh@ LVsV feysVªh deh'ku lnL; | E52: ,ds&47
A53: 52 | B53: yksdsrh pUnj mQZ izHkkdj mQZ ikndky Lokeh mQZ jfo firk jkepUnsj mez 53@21 fuoklh& xzke bljksthokM+k lnkf'ko uxj] e.My dkekjsM~Mh ftyk futkekckn rsyaxkuk | C53: Mh-ds-,l-tsM-lh@ LVsV feysVªh deh'ku lnL;@izHkkjh dEiuh ua0&10 | D53: 25 yk[k | E53: ,ds&47
A54: 53 | B54: fxj/kj mQZ ukxlq mQZ eulq rqejsVh fuoklh& xzke tosyh rglhy ,VvkiYyh Fkkuk dlulwj ftyk x<fpjkSyh | C54: Mh-ds-,l-tsM-lh lnL;] izHkkjh daiuh ua0&04 | D54: 25 yk[k | E54: ,ds&47
A55: 54 | B55: bjh eksgu jsMMh mQZ foosd mQZ HkLdj mQZ mes'k mQZ izdk'k mQZ egs'k mQZ fot; mQZ lqjsUnz firk bZjh f'kok jsM~Mh] mez 63 o"kZ] tUe frfFk 03-10-1960 tkrh & jsM~Mh] lkfdu& dksapUukiYyh fujey vkU/kzizns'k] f'k{kk & 10 ikl | C55: Mh-ds-,l-tsM-lh lnL; bZuke&25 yk[k | D55: 25 yk[k | E55: ,ds&47
A56: 55 | B56: jfurk mQZ t;efr ifr lkseth lkfdu ,sugqj Fkkuk fldlksM+ ftyk dkadsj NRrhlx<+ gqfy;k & dn 5 QhV djhcu] jax xksjh] 'kjhj lk/kkj.k] psgjk yEck] dkys yEcs cky j[krh gS] NRrhlx<+h] fgUnh] gYch] xks.Mh Hkk"kk cksyrh gSA | C56: ,ltsMlh,e- lnL; ekM+ fMohtu lfpo]dqrqy ,fj;k desVh lfpo] Hkwedky if=dk dh phQ ,fMVj | E56: ,ds&47 okdhVkdh lsB
A57: 56 | B57: uhfr mQZ mfeZyk mQZ dksis lkfdu ,ydkxq.Mk xaxkywj {ks= ftyk chtkiqj gqfy;k & dn 5-2 QhV] jax lkaoyh] yEcs cky] bdgjk] cnu] psgjk piVk fgUnh] xks.Mh] nksjyh] rsyxw cksyrh | C57: Mh-Ogh-lh- lnL; iwoZ cLrj fMohtu lfpo fMohtu izoDrk Hkwedky lans'k if=dk dh phQ ,fMVj ckjlwj ,fj;k desVh lfpo iwoZ cLrj lh-,u-,e- bapktZ | E57: ,ds&47@ vkbZdke lsV | F57: iwoZ cLrj | G57: ckjlwj
A58: 57 | B58: fueZyk mez 30@22 o"kZ djhcu tkfr n.Mkeh lkfdu rkfdyksM Fkkuk HkSjex<+ ftyk chtkiqj N0x0 gqfy;k & dn 5 QhV] jax lkaoyh] yEcs cky] iryk 'kjhj] psgjk xksy fgUnh] xks.Mh] nksjyh] cksyrh gSA | C58: Mh-Ogh-lh- lnL; iwoZ cLrj fMohtu dek.M bu phQ cks/k?kkV ,fj;k desVh lfpo | E58: ,ds&47@ vkbZdke lsV | F58: iwoZ cLrj | G58: cks/k?kkV
A59: 58 | B59: tkudw mQZ lqjs’k lyke firk fxt: lyke mez 45@22 o"kZ djhcu tkfr xks.M lkfdu NksVsQjlxkao Fkkuk Qjlxkao ftyk ukjk;.kiqj N0x0 gqfy;k & dn 5-5 QhV] jax lkaoyk] 'kjhj&lkekU;] psgjk xksy] eqN j[krk gS] fgUnh] xks.Mh] NRrhlx<+h Hkk"kk dk Kku gSA | C59: Mh-Ogh-lh- lnL; venbZ?kkVh ,fj;k desVh lfpo venbZ?kkVh ,fj;k desVh izHkkjh | E59: ,ds&47 | G59: venbZ?kkVh
A60: 59 | B60: jStw yksgkj mQZ julk; firk cTtw lyke mez 45@22 o"kZ djhcu tkfr yksgkj lkfdu ejldksy Fkkuk /kkSMkbZ ftyk ukjk;.kiqj N0x0 gqfy;k & dn 5-7 QhV djhcu] jax lkoyk] 'kjhj e/;e] eqN j[krk gS] fgUnh] gYch] xks.Mh] NRrhlx<+ cksyrk gSA | C60: Mh-Ogh-lh- lnL; c;kukj ,fj;k desVh lfpo | E60: ,ds&47 @vkbZdke lsV | G60: c;kukj
A61: 60 | B61: eqjyh lyke mez 40@22 o"kZ djhcu tkfr xks.M] lkfdu e.Mkukj Fkkuk vkekcsMk] ftyk dkadsj Nx gqfy;k & dn& e/;e] jax lkaoyk] xBhyk cnu] cky gYdk ?kq?kjkyw] eqN ugha j[krk gSA fgUnh] xks.Mh] NRrhlx<+h] gYch Hkk"kk cksyrk gSA | C61: Mh-Ogh-lh- lnL; izHkkjh fMohtu Vsyj Vhe izHkkjh fMohtu lIykbZ Vhe | E61: blakl@vkbZdke lsV
A62: 61 | B62: liuk mQZ liuDdk ifr ';ke mQZ pSrq mQZ fxjh jsM~Mh mez djhcu 55 o"kZ lkfdu xzke nkejapk ftyk x<+fpjkSyh egkjk"VªkAgqfy;k & dn 5-3 QhV djhcu] jax xksjh] 'kjhj& [kMk cnu]] psgjk yEck] dkys yEcs cky j[krh gS] fgUnh] gYch] xks.Mh] ejkBh] rsyxw Hkk"kk cksyrh gSA | C62: Mh-Ogh-lh- lnL; ekM+ fMohtu lIykbZ bapktZ baUnzorh ,fj;k turkuk ljdkj v/;{ | E62: ,ds&47 okdhVkdh lsB | F62: ekM | G62: bUnzkorh
A63: 62 | B63: e/kq mQZ deykdj mez 35@22 o"kZ djhcu lkfdu vkU/kzizns’k- gqfy;k & dn 5-5 QhV djhcu] jax dkyk] eqN j[krk gS] f’k{kk & i<+k fy[kk gS] Hkk"kk & xks.Mh] rsyxw] fgUnh Hkk"kk dk Kku gSA | C63: Mh-Ogh-lh- lnL; lfpo & bUnzkorh ,fj;k desVh | E63: ,ds&47 okdhVkdh lsB] LekVZQksu | G63: bUnzkorh
...

Sheet Pivot Table 37

Sheet Detail4
A1: Date | B1: Int Unique No | C1: Int Content | D1: Name_ | E1: Name | F1: GR | G1: Latitude | H1: Longitude | I1: Strength | J1: Int Confidence | K1: Source | L1: Type | M1: Rank | N1: Area Committee | O1: District | P1: Police Station | R1: Division | S1: Week | T1: Month
A2: No contributing data for this category

Sheet 2019
A1: Date | B1: Int Unique No | C1: Int Content | D1: Name_ | E1: Name | F1: GR | G1: Latitude | H1: Longitude | I1: Strength | J1: Int Confidence | K1: Source | L1: Type | M1: Rank | N1: Area Committee | O1: District | P1: Police Station | Q1: Place | R1: Division | S1: Week | T1: Month
A2: 1/1/2019 | C2: Distt- Narayanpur PS- Chhote Dongar Village- Gumter me East Bastar DVC Secy Niti @ Urmila ke sath0 7 armed naxalio ke upasthiti ki suchana hai | E2: Niti @ Urmila | G2: 19.316319 | H2: 81.352877 | I2: 7 | K2: SIB | M2: Secy | N2: East Bastar DVC | O2: Narayanpur | P2: Chhote Dongar | Q2: Gumter
A3: 3/1/2019 | C3: Distt- Narayanpur PS- Orcha Village- Aded me Orcha LOS Comdr Deepak Member Anita ke sath 13 armed naxalio ke upasthiti ki suchana hai | E3: Deepak (Anita) | G3: 19.292234 | H3: 81.088849 | I3: 13 | K3: SIB | M3: Comdr (Member) | N3: Orcha LOS | O3: Narayanpur | P3: Orcha | Q3: Aded
A4: 3/1/2019 | C4: Since today (03.01.19) morning a group of armed and uniformed CPI (Maoist) cadres (18-20) has been noticed camping near Temrugaon PS Dhaudai Distt Narayanpur. | E4: - | G4: 19.403025 | H4: 81.410693 | I4: 18-20 | K4: IB | M4: - | N4: - | O4: Narayanpur | P4: Dhaudai | Q4: Temrugaon
A5: 4/1/2019 | C5: Distt- Narayanpur PS- Dhaudai Village- Temrugaon me Bayanar AC Secy Nirmala ke sath 20-25 armed naxalio ke upasthiti ki suchana hai | E5: Nirmala | G5: 19.403025 | H5: 81.410693 | I5: 20-25 | K5: SIB | M5: Secy | N5: Bayanar AC | O5: Narayanpur | P5: Dhaudai | Q5: Temrugaon
A6: 4/1/2019 | C6: 1. A group of armed CPI (Maoist) cadres led by Ranita (Maad DVCS) held a villagers meeting (3-4) near village Kanagaon PS/Distt Narayanpur on 03.01.19 and discussed the formation of new government in the state. | E6: Ranita | G6: 19.761221 | H6: 81.316212 | I6: 45355 | K6: IB | M6: Secy | N6: Maad DVC | O6: Narayanpur | P6: Narayanpur | Q6: Kanagaon
A7: 4/1/2019 | C7: A group of armed CPI (Maoist) cadres (20-22) has been noticed in the areas adjacent to Pindelpara of village Murnar PS/Distt Narayanpur for the last 3-4 days. | E7: - | G7: 19.678739 | H7: 81.041032 | I7: 20-22 | K7: IB | M7: - | N7: - | O7: Narayanpur | P7: Narayanpur | Q7: Murnar
A8: 4/1/2019 | C8: Distt- Narayanpur PS- Narayanpur Village- Kakabeda me Maad DVC Secy Ranita Coy no 01 member Jagasish ke sath 20-25 armed naxalio ke upasthiti ki suchana hai | E8: Ranita (Jagadish) | G8: 19.23266 | H8: 81.313468 | I8: 20-25 | K8: SIB | M8: Secy (Member) | N8: Maad DVC (Coy no 01) | O8: Narayanpur | P8: Narayanpur | Q8: Kakabeda
A9: 5/1/2019 | C9: Distt- Narayanpur PS- Orchha Village- Chalcher me Maad DVC Suply Inch Sapna Jatlur LOS Comdr Ashok ke sath 14-15 armed naxalio ke upasthiti ki suchana hai | E9: Sapna (Ashok) | G9: 19.33184 | H9: 81.048225 | I9: 14-15 | K9: SIB | M9: Inch (Comdr) | N9: Maad DVC Suplly (Jatlur LOS) | O9: Narayanpur | P9: Orchha | Q9: Chalcher
A10: 6/1/2019 | C10: Distt- Narayanpur PS- Narayanpur Village- Pindka me Kutul AC Member Sukhlal ke sath 07-08 armed naxalio ke upasthiti ki suchana hai | E10: Sukhlal | G10: 19.541075 | H10: 81.183725 | I10: 45481 | K10: SIB | M10: Member | N10: Kutul AC | O10: Narayanpur | P10: Narayanpur | Q10: Pindka
A11: 7/1/2019 | C11: Distt- Narayanpur PS- Orchha Village- Orchhameta me Orchha LOS Comdr Deepak ke sath 10-12 armed naxalio ke upasthiti ki suchana hai | E11: Deepak | G11: 19.33713 | H11: 81.089692 | I11: 45577 | K11: SIB | M11: Comdr | N11: Orchha LOS | O11: Narayanpur | P11: Orchha | Q11: Orchhameta
A12: 8/1/2019 | C12: Distt- Narayanpur PS- Chhote Dongar Village- Dhurbeda me Agyat 08-10 armed naxalio ke upasthiti ki suchana hai. | E12: - | G12: 19.513135 | H12: 81.277286 | I12: 45514 | K12: SIB | M12: - | N12: - | O12: Narayanpur | P12: Chhote Dongar | Q12: Dhurbeda
A13: 7/1/2019 | C13: 1. A group of armed CPI (Maoist) cadres (15) led by Kalpana and Bandi (Both DVCMs Maad Division) is noticed camping at a forest about 0.5 Km West of village Gomangal PS Orcha district Narayanpur since January 7 2019. The said group came from Khodpar PS Orcha and is likely to proceed towards Hasnar PS Orcha. | E13: Kalpana & Bandi | G13: 19.420339 | H13: 81.069658 | I13: 15 | K13: IB | M13: Member | N13: Maad DVC | O13: Narayanpur | P13: Orchha | Q13: Gomgal & Hasnar
A14: 7/1/2019 | C14: 1. A group armed CPI (Maoist) cadres (30-40) led by Raju Salam Meena Mainu (leaders of Raoghat AC) were noticed camping at a forest hill (Usmal Metta Pahadi) located in the tri-junction of Dubehade Kaknar and Ranimarka PS/Dist Narayanpur on first week of January 2019. | E14: Raju Salam (Meena) (Mainu) | G14: 19.858622 | H14: 80.882643 | I14: 30-40 | K14: IB | M14: Comdr (Comdr) (Comdr) | N14: Coy no 05 (Panidobir LOS) (Charhaon LOS) | O14: Narayanpur | P14: Narayanpur | Q14: Kaknar & Ranimarka
A15: 8/1/2019 | C15: A group of armed and uniformed CPI (Maoist) cadres (08-10) of Maad DVC led by Deepak (Comdr ader LOS) was noticed 01 Km south of village Idwaya (10-11 km SW of PS Orchha) Distt. Narayanpur on January 08. | E15: Deepak | G15: 19.298838 | H15: 81.117887 | I15: 45514 | K15: IB | M15: Comdr | N15: Orcha LOS | O15: Narayanpur | P15: Orcha | Q15: Idwaya
A16: 11/1/2019 | C16: A group of armed CPI (Maoist) cadres (100) led by Raju Dada (IC East Bastar DVC) has been camping at a forest area near village Gomter, PS Orcha, Distt Narayanpur since 06.01.19 | E16: Raju Dada @ KRC | G16: 19.316319 | H16: 81.352877 | I16: - | K16: IB | M16: Member | N16: East Bastar DVC | O16: Narayanpur | P16: Orcha | Q16: Gomter
A17: 11/1/2019 | C17: Distt- Narayanpur PS- Orcha Village- Badetondabeda me Orcha LOS Comdr Deepak ke sath 08-10 armed naxalio upasthiti ki suchana hai. | E17: Deepak | G17: 19.326862 | H17: 81.132105 | I17: 45514 | K17: SIB | M17: Comdr | N17: Orcha LOS | O17: Narayanpur | P17: Orcha | Q17: Bade tondabeda
A18: 11/1/2019 | C18: Distt- Narayanpur PS- Chotedongarh Village- Becha me DVCM Niti @ Urmila ke sath 06-07 armed naxalio upasthiti ki suchana hai. | E18: Niti @ Urmila | G18: 19.330264 | H18: 81.368839 | I18: 45450 | K18: SIB | M18: Member | N18: DVC | O18: Narayanpur | P18: Chotedongarh | Q18: Becha
A19: 11/1/2019 | C19: A group of armed CPI (Maoist) cadres (35-40) led by Kosa (CCM) has been camping about 01 km west of Adingpar (40 - 42 km west of PS Orcha), Distt Narayanpur for the last 03 days. The said group is likely to stay in the said area. | E19: Kosa | G19: 19.416069 | H19: 80.979844 | I19: 35-40 | K19: IB | M19: Member | N19: CC | O19: Narayanpur | P19: Orcha | Q19: Adingpar
A20: 12/1/2019 | C20: A group of armed CPI (Maoist) cadres (15-20) led by Niti (East Bastar DVCS) has been noticed in the areas north west of village Tuswal PS Chhotedonger Distt Narayanpur since 11.01.19. Further learnt that some senior leader is likely to arrive in the areas adjoining Tuswal PS Chhotedonger Distt Narayanpur and Wakeli PS Barsoor Distt Dantewada on 14.01.19. | E20: Niti @ Urmila | G20: 19.304247 | H20: 81.366579 | I20: 15-20 | K20: IB | M20: Secy | N20: East Bastar DVC | O20: Narayanpur | P20: Chotedongarh | Q20: Tuswal
A21: 12/1/2019 | C21: Today (12.01.19) at around 1300 hrs a group of armed and uniformed CPI (Maoist) cadres (12-15) led by Somji (Member Coy No. 06 ) and Raiju Lohar (ACM Bhanpuri AC) is noticed near Maraskol PS Dhaudai Distt Narayanpur. Earlier today in morning hours the said group was noticed at Sulenga PS Chhotedonger Distt Narayanpur. | E21: Somji (Raiju Lohar) | G21: 19.467876 | H21: 81.413073 | I21: 45641 | K21: IB | M21: Member (Secy) | N21: Coy no 06 (Bhanpuri AC) | O21: Narayanpur | P21: Chotedongarh | Q21: Sulenga
A22: 13-01-2019 | C22: Distt- Narayanpur PS- Narayanpur Village- Kodeliyar me Kutul LOS comdr Pandi @ Dinesh AC Member Sukhlal ke sath 10-12 armed naxalio upasthiti ki suchana hai. | E22: Pandi @ Dinesh (Sukhlal) | G22: 19.535793 | H22: 81.071347 | I22: 45577 | K22: SIB | M22: Comdr (Member) | N22: Kutul LOS (AC) | O22: Narayanpur | P22: Narayanpur | Q22: Kodeliyar
A23: 14-01-2019 | C23: Distt- Narayanpur PS- Orchha Village- Japguda me Orchha LOS comdr Deepak ke sath 11-12 armed naxalio upasthiti ki suchana hai. | E23: Deepak | G23: 19.320493 | H23: 81.218556 | I23: 45608 | K23: SIB | M23: Comdr | N23: Orchha LOS | O23: Narayanpur | P23: Orchha | Q23: Japgunda
A24: 14-01-2019 | C24: A group of armed CPI (Maoist) cadres (40) led by Kosa (CCM) was noticed camping at Kalangur a forest hill loceted in between Adingpur and Farasbeda and about 03 kms west of village Adingpar PS Orchha Distt Narayanpur since 06-01-19. The group was likely to stay in the said location for about a fortnight | E24: Kosa | G24: 19.416069 | H24: 80.979844 | I24: 40 | K24: IB | M24: Member | N24: CC | O24: Narayanpur | P24: Orchha | Q24: Adingpar
A25: 15-01-2019 | C25: Distt- Narayanpur PS- Narayanpur Village- Ehra & Hokpad me Agyat 20-25 armed naxalio dekhe jane ki suchana hai. | E25: - | G25: 19.509569 | H25: 81.171491 | I25: 20-25 | K25: SIB | M25: - | N25: - | O25: Narayanpur | P25: Narayanpur | Q25: Ehra & Hokpad
A26: 17-01-2019 | C26: Distt- Narayanpur PS- Kukrajhor Village- Karelghati me Kutuk ACM Sukhlal ke sath 02 armed naxalio ke Dekhe Jane ki suchana hai. | E26: Sukhlal | G26: 19.620789 | H26: 81.216318 | I26: 2 | K26: SIB | M26: Member | N26: Kutul AC | O26: Narayanpur | P26: Kukrajhor | Q26: Karelghati
A27: 17-01-2019 | C27: A group of armed CPI (Maoist) cadres (60-80) including cadres of PLGA Coy No. 01 has been camping near village Kodtamarka and Parpa PS Narayanpur Distt Narayanpur since last 2-3 days. Further learnt that Maoist has called a large scale meeting near village Padamkot (66 km SW of PS Narayanpur) on 17.01.19. The meeting is likely to be attended by all senior Maoist leaders of Maad DVC | E27: - | G27: 19.467187 | H27: 80.970758 | I27: 60-80 | K27: IB | M27: Member | N27: PLGA Coy no 01 | O27: Narayanpur | P27: Narayanpur | Q27: Kodtamarka & Parpa
A28: 18-01-2019 | C28: Distt- Narayanpur PS- Orchha Village- Dhurbeda me Mad DVC Secy Ranita Kutul LOS Comdr Pandi ke sath 18-20 armed naxalio ke upasthiti ki suchana hai. | E28: Ranita (Pandi) | G28: 19.449293 | H28: 80.998164 | I28: 18-20 | K28: SIB | M28: Secy (Comdr) | N28: Mad DVC (Kutul LOS) | O28: Narayanpur | P28: Orchha | Q28: Dhurbeda
A29: 18-01-2019 | C29: Distt- Narayanpur PS- Orchha Village- Nadipara me Agyat 06-07 armed naxalio ke upasthiti ki suchana hai. | E29: - | G29: 19.355602 | H29: 81.168802 | I29: 45450 | K29: SIB | M29: - | N29: - | O29: Narayanpur | P29: Orchha | Q29: Nadipara
A30: 17-01-2019 | C30: A group of armed CPI (Maoist) cadres (25) led by Raju Salam Prasad Meena (all DVCMs of North Bastar DVC) was noticed at village Kaknar PS/Distt Narayanpur on 17.01.19. The said group is constsntly noticed moving in adjoining villages Markabeda Koroskodo Ranimarka Dubehade in Maad area Distt Narayanpur and in adjacent villages Gundul Panidobir Alparas of PS Koyalibeda Distt Kanker. | E30: Raju Salam (Meena) (Prasad) | G30: 19.859907 | H30: 80.883256 | I30: 25 | K30: IB | M30: Comdr (Comdr) (Member) | N30: Coy no 05 (Panidobir LOS) | O30: Narayanpur | P30: Narayanpur | Q30: Kaknar
A31: 19-01-2019 | C31: Distt- Narayanpur PS- Orchha Village- Gattakal me Kutul LOS Comdr Pandi @ Dinesh ke sath 10-12 armed naxalio ke upasthiti ki suchana hai. | E31: Pandi @ Dinesh | G31: 19.378786 | H31: 80.880283 | I31: 45577 | K31: SIB | M31: Comdr | N31: Kutul LOS | O31: Narayanpur | P31: Orchha | Q31: Gattakal
A32: 20-01-2019 | C32: Distt- Narayanpur PS- Orchha Village- Durginpara me Agyat 04 naxalio ke upasthiti ki suchana hai. | E32: - | G32: 19.368206 | H32: 81.174752 | I32: 4 | K32: SIB | M32: - | N32: - | O32: Narayanpur | P32: Orchha | Q32: Durginpara
A33: 20-01-2019 | C33: Distt- Narayanpur PS- Chhote Dongar Village- Kadenar & Kanhargaon Road me Reccee kiye jane ki suchana hai. | E33: - | G33: 19.35011 | H33: 81.414619 | I33: - | K33: SIB | M33: - | N33: - | O33: Narayanpur | P33: Chhhote Dongar | Q33: Kadenar & Kanhargaon
A34: 21-01-2019 | C34: Distt- Narayanpur PS- Narayanpur Village- Kehnar me Maad DVC Inch Ranita Member Somari ke sath 17-18 armed naxalio ke upasthiti ki suchana hai. | E34: Ranita (Somari) | G34: 19.502415 | H34: 80.993339 | I34: 17-18 | K34: SIB | M34: Inch (Member) | N34: Maad DVC | O34: Narayanpur | P34: Narayanpur | Q34: Kehnar
A35: 21-01-2019 | C35: A group of armed CPI (Maoist) cadres (25) led by Deepak and Ashok (leaders, Ader LOS) has been noticed camping near a nala located 0.5 km west of village Dhonderbeda, PS Orcha, Distt Narayanpur since 18.01.19. The said group has erected 03 polythene tents. | E35: Deepak (Member) | G35: 19.284009 | H35: 81.023239 | I35: 25 | K35: IB | M35: comdr | N35: Orchha LOS | O35: Narayanpur | P35: Orchha | Q35: Dhonderbeda
A36: 23-01-2019 | C36: 1. A large group of armed CPI (Maoist) cadres (70-80) has been noticed moving in the forest area of Dantewada-Narayanpur border near village Jatloor PS Orchha distt Narayanpur since Jan 22. | E36: - | G36: 19.304861 | H36: 80.965827 | I36: 70-80 | K36: IB | M36: - | N36: - | O36: Narayanpur | P36: Orchha | Q36: Jatlur
A37: 23-01-2019 | C37: Distt- Narayanpur PS- Dhanora Village- Kostadi me AC Member Sukhlal ke sath 06-07 armed naxalio upasthiti ki suchana hai. | E37: Sukhlal | G37: 19.505726 | H37: 81.155408 | I37: 45450 | K37: SIB | M37: Member | N37: AC | O37: Narayanpur | P37: Dhanora | Q37: Kostadi
A38: 23-01-2019 | C38: 1. A group of armed CPI (Maoist) cadres (13) led by Lalita (Maad DVCM) has been noticed camping near a water point located in between Kohkapara and Itepara PS Orchha Distt Narayanpur since Jan 22 2019. | E38: Lalita | G38: 19.348341 | H38: 81.045269 | I38: 13 | K38: IB | M38: Member | N38: Maad DVC | O38: Narayanpur | P38: Orchha | Q38: Kohkapara
A39: 24-01-2019 | C39: Distt- Narayanpur PS- Dhanora Village- Kostadi me AC Member Sukhlal ke sath 06-07 armed naxalio upasthiti ki suchana hai. | E39: Ranita | G39: 19.505726 | H39: 81.155408 | I39: - | K39: SIB | M39: Member | N39: Maad DVC | O39: Narayanpur | P39: Orchha | Q39: Juwada
A40: 24-01-2019 | C40: Distt- Narayanpur PS- Orchha Village- Gudadi me Agyat 05-06 armed naxalio ke dekhe jane ki suchana hai. | E40: - | G40: 19.343423 | H40: 81.202769 | I40: 45418 | K40: SIB | M40: - | N40: - | O40: Narayanpur | P40: Orchha | Q40: Gudadi
...

Sheet 2020
A1: Date | B1: Int Unique No | C1: Int Content | D1: Name_ | E1: Name | F1: GR | G1: Latitude | H1: Longitude | I1: Strength | J1: Int Confidence | K1: Source | L1: Type | M1: Rank | N1: Area Committee | O1: District | P1: Police Station | Q1: Place | R1: Division | S1: Week | T1: Month
A2: 43862 | C2: Distt- Narayanpur PS- Orchha Village- Bhatbeda me Orchha LOS Comdr Deepak ke sath 14-15 armed naxalio ke upasthiti ki suchana hai | D2: dpk | E2: Deepak | G2: 19.286266 | H2: 81.141885 | I2: 14-15 | K2: SIB | M2: comdr | N2: Orchha LOS | O2: Narayanpur | P2: Orchha | Q2: Bhatbeda
A3: 43922 | C3: Distt- Narayanpur PS- Orchha Village- Bhatbeda me Pln no 16 Comdr Mallesh ke sath 18-20 armed naxalio upasthiti ki suchana hai | D3: mls | E3: Mallesh | G3: 19.286266 | H3: 81.141885 | I3: 18-20 | K3: SIB | M3: Comdr | N3: Pln no 16 | O3: Narayanpur | P3: Orchha | Q3: Bhatbeda
A4: 43983 | C4: Distt- Narayanpur PS- Orcha Village- Bhatbeda me Pln no 16 Comdr Mallesh ke sath 20-25 armed naxalio ke upasthiti ki suchana hai | D4: mls | E4: Mallesh | G4: 19.286266 | H4: 81.141885 | I4: 20-25 | K4: SIB | M4: Comdr | N4: Pln no 16 | O4: Narayanpur | P4: Orcha | Q4: Bhatbeda
A5: 44044 | C5: Distt- Narayanpur PS- Narayanpur Village- Enmeta me Kutul LOS Comdr Pandi @ Dinesh ke sath 07-08 armed naxalio ke upasthiti ki suchana hai | D5: pdi | E5: Pandi @ Dinesh | G5: 19.602297 | H5: 81.154946 | I5: 45481 | K5: SIB | M5: Comdr | N5: Kutul LOS | O5: Narayanpur | P5: Narayanpur | Q5: Enmeta
A6: 44044 | C6: Distt- Narayanpur PS- Orcha Village- Kunjekal me Agyat Maoist naxalio ke Villagers Meeting Kiye Janea ki suchana hai | D6: ukn | E6: - | G6: 19.337039 | H6: 81.007573 | I6: - | K6: SIB | M6: - | N6: - | O6: Narayanpur | P6: Orcha | Q6: Kunjkal
A7: 44075 | C7: Distt- Narayanpur PS- Kohkameta Village- Gadawahi me Kutul AC Member Sukhlal ke sath 08-09 armed naxalio ke upasthiti ki suchana hai | D7: skl | E7: Sukhlal | G7: 19.652004 | H7: 81.049647 | I7: 45513 | K7: SIB | M7: Member | N7: Kutul AC | O7: Narayanpur | P7: Kohkameta | Q7: Gadawahi
A8: 44105 | C8: Distt- Narayanpur PS- Orchha Village- Bhatbeda me Orchha LOS Comdr Deepak ke sath 12-13 armed naxalio ke upasthiti ki suchana hai | D8: dpk | E8: Deeapak | G8: 19.286266 | H8: 81.141885 | I8: 45639 | K8: SIB | M8: Comdr | N8: Orchha LOS | O8: Narayanpur | P8: Orchha | Q8: Bhatbeda
A9: 44105 | C9: Distt- Narayanpur PS- Narayanpur Village- Kutul (Parpa) to me Maad DVC Secy Ranita @ Jaimati ke sath 15-20 armed naxalio ke upasthiti ki suchana hai | D9: rnt | E9: Ranita @ Jaimati | G9: 19.518649 | H9: 81.006457 | I9: 15-20 | K9: SIB | M9: Secy | N9: Mad DVC | O9: Narayanpur | P9: Narayanpur | Q9: Kutul (Parpa)
A10: 44166 | C10: Distt- Narayanpur Camp- Sonpur Village- Horadi me Paralkot LOS Comdr Jailal @ Anant ke sath 10-12 armed naxalio ke upasthiti ki suchana hai. | E10: Jailal @ Anant | G10: 19.751235 | H10: 80.889104 | I10: 45577 | K10: SIB | M10: Comdr | N10: Paralkot LOS | O10: Narayanpur | P10: Camp Sonpur | Q10: Horadi
A11: 44166 | C11: Distt- Narayanpur Camp- Sonpur Village- Gongla me Kohkameta LOS Comdr Reena ke sath 07-08 armed naxalio ke upasthiti ki suchana hai. | D11: rna | E11: Reena | G11: 19.678468 | H11: 81.01788 | I11: 45481 | K11: SIB | M11: Comdr | N11: Kohkameta LOS | O11: Narayanpur | P11: Camp Sonpur | Q11: Gongla
A12: 13-01-2020 | C12: Distt- Narayanpur PS- Orchha Village- Rotad me Pln no 16 Comdr Mallesh ke sath 18-20 armed naxalio ke upasthiti ki suchana hai. | D12: mls | E12: Mallesh | G12: 19.313468 | H12: 81.238715 | I12: 18-20 | K12: SIB | M12: Comdr | N12: Pln no 16 | O12: Narayanpur | P12: Orchha | Q12: Rotad
A13: 14-01-2020 | C13: Distt- Narayanpur PS- Kohkameta Village-Mohandi me Kutul AC Member Dosel & Veshu ke sath 07-08 armed naxalio ke upasthiti ki suchana hai. | D13: dsl | E13: Dosel (Veshu) | G13: 19.564163 | H13: 81.077036 | I13: 45481 | K13: SIB | M13: Member | N13: Kutul AC | O13: Narayanpur | P13: Camp Kohkameta | Q13: Mohandi
A14: 14-01-2020 | C14: Distt- Narayanpur PS- Dhanora Village- Tekanar & Rainar me Agyat 04-05 armed naxalio ke upasthiti ki suchana hai. | D14: ukn | G14: 19.427974 | H14: 81.206415 | I14: 45387 | K14: SIB | M14: - | N14: - | O14: Narayanpur | P14: Dhanora | Q14: Tekanar & Rainar
A15: 15-01-2020 | C15: Distt- Narayanpur PS- Orcha Village- Ader me Maad DVC Suply Comdr Sapna Orcha LOS Comdr Deepak Member Anita ke sath 15 armed naxalio ke upasthiti ki suchana hai. | D15: spn | E15: Sapna (Deepak) (Anita) | G15: 19.289862 | H15: 81.089398 | I15: 15 | K15: SIB | M15: Comdr (Comdr) (Member) | N15: Maad DVC Suply (Orcha LOS) | O15: Narayanpur | P15: Orcha | Q15: Ader
A16: 16-01-2020 | C16: Distt- Narayanpur PS- Narayanpur Village-Pallakasa me Agyat 25-30 armed naxalio ke upasthiti ki suchana hai. | D16: ukn | E16: - | G16: 19.772999 | H16: 81.106177 | I16: 25-30 | K16: SIB | M16: - | N16: - | O16: Narayanpur | P16: Narayanpur | Q16: Pallakasa
A17: 17-01-2020 | C17: Distt- Narayanpur PS- Narayanpur Village-Murehnar me Agyat 07-08 armed naxalio ke upasthiti ki suchana hai. | D17: ukn | E17: - | G17: 19.574784 | H17: 81.194668 | I17: 45481 | K17: SIB | M17: - | N17: - | O17: Narayanpur | P17: Kukadajhor | Q17: Murehnar
A18: 19-01-2020 | C18: Distt- Narayanpur PS- Orchha Village- Bade Tondabeda me Orchha LOS Comdr Deepak member Jyoti ke sath dekhe jane ki suchana hai. | D18: dpk | E18: Deepak (Jyoti) | G18: 19.326977 | H18: 81.133264 | I18: - | K18: SIB | M18: Comdr (Member) | N18: Orchha LOS | O18: Narayanpur | P18: Orchha | Q18: Bade Tondabeda
A19: 19-01-2020 | C19: Distt- Narayanpur PS- Kohkameta Village- Toke me Kohkameta LOS Comdr Reena ke sath 08-10 armed naxalio ke upasthiti ki suchana hai. | D19: rna | E19: Reena | G19: 19.571523 | H19: 80.985565 | I19: 45514 | K19: SIB | M19: Comdr | N19: Kohkameta LOS | O19: Narayanpur | P19: Kohkameta | Q19: Toke
A20: 19-01-2020 | C20: Distt- Narayanpur PS- Orchha Village- Markabeda me Maad DVC Suply Inch Sapna ke sath 14-15 armed naxalio ke upasthiti ki suchana hai. | D20: spn | E20: Sapan | G20: 19.28744 | H20: 81.17095 | I20: 14-15 | K20: SIB | M20: Inch | N20: Maad DVC Suply | O20: Narayanpur | P20: Orchha | Q20: Markabeda
A21: 19-01-2020 | C21: Distt- Narayanpur PS- Orchha Village- Kostadi me Kutul LOS Comdr Pandi @ Dinesh ke sath 09-10 armed naxalio ke upasthiti ki suchana hai. | D21: pdi | E21: Pandi @ Dinesh | G21: 19.487974 | H21: 81.156826 | I21: 45545 | K21: SIB | M21: Comdr | N21: Kutul LOS | O21: Narayanpur | P21: Orchha | Q21: Kostadi
